<mujoco model="humanoid">
  <!-- <compiler coordinate="local"/> -->
  <compiler coordinate="local" inertiafromgeom="true" angle="degree"/>
  <statistic extent="2" center="0 0 1"/>
  <!-- <option timestep="0.00555"/> -->
  <option timestep="0.003"/>

  <custom>
        <!-- brax custom params -->
        <numeric data="2500" name="constraint_limit_stiffness"/>
        <numeric data="27000" name="constraint_stiffness"/>
        <numeric data="30" name="constraint_ang_damping"/>
        <numeric data="80" name="constraint_vel_damping"/>
        <numeric data="-0.05" name="ang_damping"/>
        <numeric data="0.5" name="joint_scale_pos"/>
        <numeric data="0.1" name="joint_scale_ang"/>
        <numeric data="0" name="spring_mass_scale"/>
        <numeric data="1" name="spring_inertia_scale"/>
        <numeric data="20" name="matrix_inv_iterations"/>
        <numeric data="15" name="solver_maxls"/>
    </custom>

  <default>
    <motor ctrlrange="-.4 .4" ctrllimited="true"/>
    <!-- <geom type="capsule" condim="3" friction="1.0 0.05 0.05" solimp=".9 .99 .003" solref=".015 1" density="1500"/> -->
    <!-- <geom type="sphere" condim="3" friction="1.0 0.05 0.05" solimp=".9 .99 .003" solref=".015 1" density="1500"/> -->
    <geom condim="3" material="geom" friction="1.0 0.05 0.05" solimp=".9 .99 .003" solref=".02 1" density="1500"/>
    <joint type="hinge" damping="6" stiffness="10" armature=".007" limited="true" solimplimit="0 .99 .01"/>
    <site size=".04" group="3"/>
    <default class="force-torque">
      <site type="box" size=".01 .01 .02" rgba="1 0 0 1"/>
    </default>
    <default class="touch">
      <site type="capsule" rgba="0 0 1 .3"/>
    </default>
  </default>
  <asset>
    <texture type="skybox" builtin="gradient" rgb1=".4 .5 .6" rgb2="0 0 0" width="100" height="100"/>
    <texture builtin="flat" height="1278" mark="cross" markrgb="1 1 1" name="texgeom" random="0.01" rgb1="0.8 0.6 0.4" rgb2="0.8 0.6 0.4" type="cube" width="127"/>
    <texture builtin="checker" height="100" name="texplane" rgb1="0 0 0" rgb2="0.8 0.8 0.8" type="2d" width="100"/>
    <material name="MatPlane" reflectance="0.5" shininess="1" specular="1" texrepeat="60 60" texture="texplane"/>
    <material name="geom" texture="texgeom" texuniform="true"/>
  </asset>
  <worldbody>
    <light cutoff="100" diffuse="1 1 1" dir="0 0 -0.1" directional="true" exponent="1" pos="0 0 10" specular=".1 .1 .1"/>
    <geom conaffinity="1" condim="3" name="floor" pos="0 0 0" rgba="0.8 0.9 0.8 1" size="100 100 .2" type="plane" material="MatPlane"/>

    <body name="Pelvis" pos="0 0 0.9205">
      
      <freejoint name="Pelvis"/>

      <geom type="sphere" size="0.0942" pos="0.0000 0.0000 0.0000"/>

      <body name="L_Hip" pos="-0.00555 0.0686 -0.09095">
        
        <joint name="L_Hip_z_transl" solreflimit="0.02 1" solimplimit="0.95 0.99 0.1" type="slide" pos="0 0 0" axis="0 0 1" range="-1 1" stiffness="0" damping="0" limited="true"/>

        <joint name="L_Hip_x" type="hinge" pos="0 0 0" axis="1 0 0" armature="0.02" range="-90.0000 90.0000" stiffness="100"/>
        <joint name="L_Hip_y" type="hinge" pos="0 0 0" axis="0 1 0" armature="0.02" range="-90.0000 90.0000" stiffness="100"/>
        <joint name="L_Hip_z" type="hinge" pos="0 0 0" axis="0 0 1" armature="0.02" range="-90.0000 90.0000" stiffness="100"/>

        <geom type="capsule" fromto="-0.00135 0.0073 -0.07575 -0.00535 0.029 -0.30315" size="0.06105"/>

        <body name="L_Knee" pos="-0.0067 0.0363 -0.3789">
          
          <joint name="L_Knee_z_transl" solreflimit="0.02 1" solimplimit="0.95 0.99 0.1" type="slide" pos="0 0 0" axis="0 0 1" range="-1 1" stiffness="0" damping="0" limited="true"/>

          <joint name="L_Knee_x" type="hinge" pos="0 0 0" axis="1 0 0" armature="0.02" range="-5.6250 5.6250" stiffness="10"/>
          <joint name="L_Knee_y" type="hinge" pos="0 0 0" axis="0 1 0" armature="0.02" range="0.0000 180.0000" stiffness="10"/>
          <joint name="L_Knee_z" type="hinge" pos="0 0 0" axis="0 0 1" armature="0.02" range="-5.6250 5.6250" stiffness="10"/>

          <geom type="capsule" fromto="0.0001 -0.00295 -0.07965 -0.0344 -0.01175 -0.31855" size="0.0541"/>

          <body name="L_Ankle" pos="-0.043 -0.0147 -0.3982">
            
            <joint name="L_Ankle_z_transl" solreflimit="0.02 1" solimplimit="0.95 0.99 0.1" type="slide" pos="0 0 0" axis="0 0 1" range="-1 1" stiffness="0" damping="0" limited="true"/>

            <joint name="L_Ankle_x" type="hinge" pos="0 0 0" axis="1 0 0" armature="0.02" range="-45.0000 45.0000" stiffness="10"/>
            <joint name="L_Ankle_y" type="hinge" pos="0 0 0" axis="0 1 0" armature="0.02" range="-90.0000 90.0000" stiffness="10"/>
            <joint name="L_Ankle_z" type="hinge" pos="0 0 0" axis="0 0 1" armature="0.02" range="-45.0000 45.0000" stiffness="10"/>
            
            <geom type="box" pos="0.0596 0.0132 -0.0279" size="0.08575 0.0483 0.0208" quat="1.0000 0.0000 0.0000 0.0000"/>
            
            <body name="L_Toe" pos="0.1213 0.0259 -0.05195">
              
              <joint name="L_Toe_x_transl" solreflimit="0.02 1" solimplimit="0.95 0.99 0.1" type="slide" pos="0 0 0" axis="1 0 0" range="-1 1" stiffness="0" damping="0" limited="true"/>

              <joint name="L_Toe_x" type="hinge" pos="0 0 0" axis="1 0 0" armature="0.02" range="-180.0000 180.0000" stiffness="10"/>
              <joint name="L_Toe_y" type="hinge" pos="0 0 0" axis="0 1 0" armature="0.02" range="-180.0000 180.0000" stiffness="10"/>
              <joint name="L_Toe_z" type="hinge" pos="0 0 0" axis="0 0 1" armature="0.02" range="-180.0000 180.0000" stiffness="10"/>
              
              <geom type="box" pos="0.0606 -0.0132 0.0270" size="0.01985 0.04785 0.0208" quat="1.0000 0.0000 0.0000 0.0000"/>
            </body>
          </body>
        </body>
      </body>
      <body name="R_Hip" pos="-0.00555 -0.0686 -0.09095">
        
        <joint name="R_Hip_z_transl" solreflimit="0.02 1" solimplimit="0.95 0.99 0.1" type="slide" pos="0 0 0" axis="0 0 1" range="-1 1" stiffness="0" damping="0" limited="true"/>

        <joint name="R_Hip_x" type="hinge" pos="0 0 0" axis="1 0 0" armature="0.02" range="-90.0000 90.0000" stiffness="100"/>
        <joint name="R_Hip_y" type="hinge" pos="0 0 0" axis="0 1 0" armature="0.02" range="-90.0000 90.0000" stiffness="100"/>
        <joint name="R_Hip_z" type="hinge" pos="0 0 0" axis="0 0 1" armature="0.02" range="-90.0000 90.0000" stiffness="100"/>
        
        <geom type="capsule" fromto="-0.00135 -0.0073 -0.07575 -0.00535 -0.029 -0.30315" size="0.06105"/>
        
        <body name="R_Knee" pos="-0.0067 -0.0363 -0.3789">
          
          <joint name="R_Knee_z_transl" solreflimit="0.02 1" solimplimit="0.95 0.99 0.1" type="slide" pos="0 0 0" axis="0 0 1" range="-1 1" stiffness="0" damping="0" limited="true"/>

          <joint name="R_Knee_x" type="hinge" pos="0 0 0" axis="1 0 0" armature="0.02" range="-5.6250 5.6250" stiffness="10"/>
          <joint name="R_Knee_y" type="hinge" pos="0 0 0" axis="0 1 0" armature="0.02" range="0.0000 180.0000" stiffness="10"/>
          <joint name="R_Knee_z" type="hinge" pos="0 0 0" axis="0 0 1" armature="0.02" range="-5.6250 5.6250" stiffness="10"/>
          
          <geom type="capsule" fromto="0.0001 0.00295 -0.07965 -0.0344 0.01175 -0.31855" size="0.0541"/>
          
          <body name="R_Ankle" pos="-0.043 0.0147 -0.3982">
            
            <joint name="R_Ankle_z_transl" solreflimit="0.02 1" solimplimit="0.95 0.99 0.1" type="slide" pos="0 0 0" axis="0 0 1" range="-1 1" stiffness="0" damping="0" limited="true"/>

            <joint name="R_Ankle_x" type="hinge" pos="0 0 0" axis="1 0 0" armature="0.02" range="-45.0000 45.0000" stiffness="10"/>
            <joint name="R_Ankle_y" type="hinge" pos="0 0 0" axis="0 1 0" armature="0.02" range="-90.0000 90.0000" stiffness="10"/>
            <joint name="R_Ankle_z" type="hinge" pos="0 0 0" axis="0 0 1" armature="0.02" range="-45.0000 45.0000" stiffness="10"/>
            
            <geom type="box" pos="0.0617 -0.0127 -0.0241" size="0.08575 0.0483 0.0208" quat="1.0000 0.0000 0.0000 0.0000"/>
            
            <body name="R_Toe" pos="0.1213 -0.0259 -0.05195">
              
              <joint name="R_Toe_x_transl" solreflimit="0.02 1" solimplimit="0.95 0.99 0.1" type="slide" pos="0 0 0" axis="1 0 0" range="-1 1" stiffness="0" damping="0" limited="true"/>

              <joint name="R_Toe_x" type="hinge" pos="0 0 0" axis="1 0 0" armature="0.02" range="-180.0000 180.0000" stiffness="10"/>
              <joint name="R_Toe_y" type="hinge" pos="0 0 0" axis="0 1 0" armature="0.02" range="-180.0000 180.0000" stiffness="10"/>
              <joint name="R_Toe_z" type="hinge" pos="0 0 0" axis="0 0 1" armature="0.02" range="-180.0000 180.0000" stiffness="10"/>
              
              <geom type="box" pos="0.0627 0.0127 0.0249" size="0.01985 0.04785 0.0208" quat="1.0000 0.0000 0.0000 0.0000"/>
            </body>
          </body>
        </body>
      </body>
      <body name="Torso" pos="-0.0267 0.0 0.109">
        
        <camera name="track" mode="trackcom" pos="0 -4 0" xyaxes="1 0 0 0 0 1"/>
        
        <joint name="Torso_z_transl" solreflimit="0.02 1" solimplimit="0.95 0.99 0.1" type="slide" pos="0 0 0" axis="0 0 1" range="-1 1" stiffness="0" damping="0" limited="true"/>

        <joint name="Torso_x" type="hinge" pos="0 0 0" axis="1 0 0" armature="0.02" range="-60.0000 60.0000" damping="10" stiffness="500"/>
        <joint name="Torso_y" type="hinge" pos="0 0 0" axis="0 1 0" armature="0.02" range="-60.0000 60.0000" damping="10" stiffness="500"/>
        <joint name="Torso_z" type="hinge" pos="0 0 0" axis="0 0 1" armature="0.02" range="-60.0000 60.0000" damping="10" stiffness="500"/>
        
        <geom type="capsule" fromto="0.0005 0.0025 0.0608 0.0006 0.003 0.0743" size="0.0769"/>
        
        <body name="Spine" pos="0.0011 0.0 0.1352">
          
          <joint name="Spine_z_transl" solreflimit="0.02 1" solimplimit="0.95 0.99 0.1" type="slide" pos="0 0 0" axis="0 0 1" range="-1 1" stiffness="0" damping="0" limited="true"/>

          <joint name="Spine_x" type="hinge" pos="0 0 0" axis="1 0 0" armature="0.02" range="-60.0000 60.0000" stiffness="100"/>
          <joint name="Spine_y" type="hinge" pos="0 0 0" axis="0 1 0" armature="0.02" range="-60.0000 60.0000" stiffness="100"/>
          <joint name="Spine_z" type="hinge" pos="0 0 0" axis="0 0 1" armature="0.02" range="-60.0000 60.0000" stiffness="100"/>
          
          <geom type="capsule" fromto="0.0114 0.0007 0.0238 0.014 0.0008 0.0291" size="0.0755"/>
          
          <body name="Chest" pos="0.0254 0.0 0.0529">
            
            <joint name="Chest_z_transl" solreflimit="0.02 1" solimplimit="0.95 0.99 0.1" type="slide" pos="0 0 0" axis="0 0 1" range="-1 1" stiffness="0" damping="0" limited="true"/>

            <joint name="Chest_x" type="hinge" pos="0 0 0" axis="1 0 0" armature="0.02" range="-60.0000 60.0000" stiffness="100"/>
            <joint name="Chest_y" type="hinge" pos="0 0 0" axis="0 1 0" armature="0.02" range="-60.0000 60.0000" stiffness="100"/>
            <joint name="Chest_z" type="hinge" pos="0 0 0" axis="0 0 1" armature="0.02" range="-60.0000 60.0000" stiffness="100"/>
            
            <geom type="capsule" fromto="-0.0173 -0.0009 0.0682 -0.0212 -0.001 0.0833" size="0.1002"/>
            
            <body name="Neck" pos="-0.0429 0.0 0.2139">
              
              <joint name="Neck_z_transl" solreflimit="0.02 1" solimplimit="0.95 0.99 0.1" type="slide" pos="0 0 0" axis="0 0 1" range="-1 1" stiffness="0" damping="0" limited="true"/>

              <joint name="Neck_x" type="hinge" pos="0 0 0" axis="1 0 0" armature="0.02" range="-5.6250 5.6250" stiffness="10"/>
              <joint name="Neck_y" type="hinge" pos="0 0 0" axis="0 1 0" armature="0.02" range="-90.0000 90.0000" stiffness="10"/>
              <joint name="Neck_z" type="hinge" pos="0 0 0" axis="0 0 1" armature="0.02" range="-90.0000 90.0000" stiffness="10"/>
              
              <geom type="capsule" fromto="0.0103 0.001 0.013 0.0411 0.0041 0.052" size="0.0436"/>
              
              <body name="Head" pos="0.0513 0.0 0.065">
                
                <joint name="Head_z_transl" solreflimit="0.02 1" solimplimit="0.95 0.99 0.1" type="slide" pos="0 0 0" axis="0 0 1" range="-1 1" stiffness="0" damping="0" limited="true"/>

                <joint name="Head_x" type="hinge" pos="0 0 0" axis="1 0 0" armature="0.02" range="-5.6250 5.6250" stiffness="10"/>
                <joint name="Head_y" type="hinge" pos="0 0 0" axis="0 1 0" armature="0.02" range="-90.0000 90.0000" stiffness="10"/>
                <joint name="Head_z" type="hinge" pos="0 0 0" axis="0 0 1" armature="0.02" range="-90.0000 90.0000" stiffness="10"/>
                
                <geom type="sphere" size="0.1011" pos="0.0000 0.0000 0.0000"/>
              </body>
            </body>
            
            <body name="L_Thorax" pos="-0.03635 0.0803 0.12025">
              
              <joint name="L_Thorax_y_transl" solreflimit="0.02 1" solimplimit="0.95 0.99 0.1" type="slide" pos="0 0 0" axis="0 1 0" range="-1 1" stiffness="0" damping="0" limited="true"/>

              <joint name="L_Thorax_x" type="hinge" pos="0 0 0" axis="1 0 0" armature="0.02" range="-5.6250 5.6250" stiffness="100"/>
              <joint name="L_Thorax_y" type="hinge" pos="0 0 0" axis="0 1 0" armature="0.02" range="-5.6250 5.6250" stiffness="100"/>
              <joint name="L_Thorax_z" type="hinge" pos="0 0 0" axis="0 0 1" armature="0.02" range="-5.6250 5.6250" stiffness="100"/>
              
              <geom type="capsule" fromto="-0.0018 0.0187 0.0063 -0.0072 0.0748 0.0252" size="0.0516"/>
              
              <body name="L_Shoulder" pos="-0.009 0.0935 0.03155">
                
                <joint name="L_Shoulder_y_transl" solreflimit="0.02 1" solimplimit="0.95 0.99 0.1" type="slide" pos="0 0 0" axis="0 1 0" range="-1 1" stiffness="0" damping="0" limited="true"/>

                <joint name="L_Shoulder_x" type="hinge" pos="0 0 0" axis="1 0 0" armature="0.02" range="-720.0000 720.0000" stiffness="10"/>
                <joint name="L_Shoulder_y" type="hinge" pos="0 0 0" axis="0 1 0" armature="0.02" range="-720.0000 720.0000" stiffness="10"/>
                <joint name="L_Shoulder_z" type="hinge" pos="0 0 0" axis="0 0 1" armature="0.02" range="-720.0000 720.0000" stiffness="10"/>
                
                <geom type="capsule" fromto="-0.0049 0.0513 -0.00265 -0.01955 0.20535 -0.01045" size="0.0524"/>
                
                <body name="L_Elbow" pos="-0.02445 0.25665 -0.01305">
                  
                  <joint name="L_Elbow_y_transl" solreflimit="0.02 1" solimplimit="0.95 0.99 0.1" type="slide" pos="0 0 0" axis="0 1 0" range="-1 1" stiffness="0" damping="0" limited="true"/>

                  <joint name="L_Elbow_x" type="hinge" pos="0 0 0" axis="1 0 0" armature="0.02" range="-5.6250 5.6250" stiffness="10"/>
                  <joint name="L_Elbow_y" type="hinge" pos="0 0 0" axis="0 1 0" armature="0.02" range="-5.6250 5.6250" stiffness="10"/>
                  <joint name="L_Elbow_z" type="hinge" pos="0 0 0" axis="0 0 1" armature="0.02" range="-180.0000 0.0000" stiffness="10"/>
                  
                  <geom type="capsule" fromto="-0.00065 0.05045 0.0017 -0.00265 0.2018 0.0067" size="0.04065"/>
                  
                  <body name="L_Wrist" pos="-0.0034 0.25225 0.0084">
                    
                    <joint name="L_Wrist_y_transl" solreflimit="0.02 1" solimplimit="0.95 0.99 0.1" type="slide" pos="0 0 0" axis="0 1 0" range="-1 1" stiffness="0" damping="0" limited="true"/>

                    <joint name="L_Wrist_x" type="hinge" pos="0 0 0" axis="1 0 0" armature="0.02" range="-180.0000 180.0000" stiffness="10"/>
                    <joint name="L_Wrist_y" type="hinge" pos="0 0 0" axis="0 1 0" armature="0.02" range="-180.0000 180.0000" stiffness="10"/>
                    <joint name="L_Wrist_z" type="hinge" pos="0 0 0" axis="0 0 1" armature="0.02" range="-180.0000 180.0000" stiffness="10"/>
                    
                    <geom type="capsule" fromto="-0.00255 0.01685 -0.0014 -0.01015 0.06745 -0.0057" size="0.0322"/>
                    
                    <body name="L_Hand" pos="-0.0126 0.0843 -0.00715">
                    
                      <joint name="L_Hand_y_transl" solreflimit="0.02 1" solimplimit="0.95 0.99 0.1" type="slide" pos="0 0 0" axis="0 1 0" range="-1 1" stiffness="0" damping="0" limited="true"/>

                      <joint name="L_Hand_x" type="hinge" pos="0 0 0" axis="1 0 0" armature="0.02" range="-180.0000 180.0000" stiffness="10"/>
                      <joint name="L_Hand_y" type="hinge" pos="0 0 0" axis="0 1 0" armature="0.02" range="-180.0000 180.0000" stiffness="10"/>
                      <joint name="L_Hand_z" type="hinge" pos="0 0 0" axis="0 0 1" armature="0.02" range="-180.0000 180.0000" stiffness="10"/>
                      <geom type="sphere" size="0.03385" pos="0.0000 0.0000 0.0000"/>
                    </body>
                  </body>
                </body>
              </body>
            </body>
            
            <body name="R_Thorax" pos="-0.03635 -0.0803 0.12025">
            
              <joint name="R_Thorax_y_transl" solreflimit="0.02 1" solimplimit="0.95 0.99 0.1" type="slide" pos="0 0 0" axis="0 1 0" range="-1 1" stiffness="0" damping="0" limited="true"/>

              <joint name="R_Thorax_x" type="hinge" pos="0 0 0" axis="1 0 0" armature="0.02" range="-5.6250 5.6250" stiffness="100"/>
              <joint name="R_Thorax_y" type="hinge" pos="0 0 0" axis="0 1 0" armature="0.02" range="-5.6250 5.6250" stiffness="100"/>
              <joint name="R_Thorax_z" type="hinge" pos="0 0 0" axis="0 0 1" armature="0.02" range="-5.6250 5.6250" stiffness="100"/>
             
              <geom type="capsule" fromto="-0.0018 -0.0187 0.0063 -0.0072 -0.0748 0.0252" size="0.0516"/>
             
              <body name="R_Shoulder" pos="-0.009 -0.0935 0.03155">
             
                <joint name="R_Shoulder_y_transl" solreflimit="0.02 1" solimplimit="0.95 0.99 0.1" type="slide" pos="0 0 0" axis="0 1 0" range="-1 1" stiffness="0" damping="0" limited="true"/>

                <joint name="R_Shoulder_x" type="hinge" pos="0 0 0" axis="1 0 0" armature="0.02" range="-720.0000 720.0000" stiffness="10"/>
                <joint name="R_Shoulder_y" type="hinge" pos="0 0 0" axis="0 1 0" armature="0.02" range="-720.0000 720.0000" stiffness="10"/>
                <joint name="R_Shoulder_z" type="hinge" pos="0 0 0" axis="0 0 1" armature="0.02" range="-720.0000 720.0000" stiffness="10"/>
               
                <geom type="capsule" fromto="-0.0049 -0.0513 -0.00265 -0.01955 -0.20535 -0.01045" size="0.0524"/>
               
                <body name="R_Elbow" pos="-0.02445 -0.25665 -0.01305">
               
                  <joint name="R_Elbow_y_transl" solreflimit="0.02 1" solimplimit="0.95 0.99 0.1" type="slide" pos="0 0 0" axis="0 1 0" range="-1 1" stiffness="0" damping="0" limited="true"/>

                  <joint name="R_Elbow_x" type="hinge" pos="0 0 0" axis="1 0 0" armature="0.02" range="-5.6250 5.6250" stiffness="10"/>
                  <joint name="R_Elbow_y" type="hinge" pos="0 0 0" axis="0 1 0" armature="0.02" range="-5.6250 5.6250" stiffness="10"/>
                  <joint name="R_Elbow_z" type="hinge" pos="0 0 0" axis="0 0 1" armature="0.02" range="0.0000 180.0000" stiffness="10"/>
                 
                  <geom type="capsule" fromto="-0.00065 -0.05045 0.0017 -0.00265 -0.2018 0.0067" size="0.04065"/>
                 
                  <body name="R_Wrist" pos="-0.0034 -0.25225 0.0084">
                 
                    <joint name="R_Wrist_y_transl" solreflimit="0.02 1" solimplimit="0.95 0.99 0.1" type="slide" pos="0 0 0" axis="0 1 0" range="-1 1" stiffness="0" damping="0" limited="true"/>

                    <joint name="R_Wrist_x" type="hinge" pos="0 0 0" axis="1 0 0" armature="0.02" range="-180.0000 180.0000" stiffness="10"/>
                    <joint name="R_Wrist_y" type="hinge" pos="0 0 0" axis="0 1 0" armature="0.02" range="-180.0000 180.0000" stiffness="10"/>
                    <joint name="R_Wrist_z" type="hinge" pos="0 0 0" axis="0 0 1" armature="0.02" range="-180.0000 180.0000" stiffness="10"/>
                   
                    <geom type="capsule" fromto="-0.00255 -0.01685 -0.0014 -0.01015 -0.06745 -0.0057" size="0.0322"/>
                   
                    <body name="R_Hand" pos="-0.0126 -0.0843 -0.00715">
                   
                      <joint name="R_Hand_y_transl" solreflimit="0.02 1" solimplimit="0.95 0.99 0.1" type="slide" pos="0 0 0" axis="0 1 0" range="-1 1" stiffness="0" damping="0" limited="true"/>

                      <joint name="R_Hand_x" type="hinge" pos="0 0 0" axis="1 0 0" armature="0.02" range="-180.0000 180.0000" stiffness="10"/>
                      <joint name="R_Hand_y" type="hinge" pos="0 0 0" axis="0 1 0" armature="0.02" range="-180.0000 180.0000" stiffness="10"/>
                      <joint name="R_Hand_z" type="hinge" pos="0 0 0" axis="0 0 1" armature="0.02" range="-180.0000 180.0000" stiffness="10"/>
                      <geom type="sphere" size="0.03385" pos="0.0000 0.0000 0.0000"/>
                    </body>
                  </body>
                </body>
              </body>
            </body>
          </body>
        </body>
      </body>
    </body>
  </worldbody>
  <actuator>
    <motor name="L_Hip_x" joint="L_Hip_x" gear="100"/>
    <motor name="L_Hip_y" joint="L_Hip_y" gear="300"/>
    <motor name="L_Hip_z" joint="L_Hip_z" gear="100"/>
    <motor name="L_Knee_x" joint="L_Knee_x" gear="75"/>
    <motor name="L_Knee_y" joint="L_Knee_y" gear="100"/>
    <motor name="L_Knee_z" joint="L_Knee_z" gear="50"/>
    <motor name="L_Ankle_x" joint="L_Ankle_x" gear="75"/>
    <motor name="L_Ankle_y" joint="L_Ankle_y" gear="100"/>
    <motor name="L_Ankle_z" joint="L_Ankle_z" gear="50"/>
    <motor name="L_Toe_x" joint="L_Toe_x" gear="25"/>
    <motor name="L_Toe_y" joint="L_Toe_y" gear="25"/>
    <motor name="L_Toe_z" joint="L_Toe_z" gear="25"/>
    <motor name="R_Hip_x" joint="R_Hip_x" gear="100"/>
    <motor name="R_Hip_y" joint="R_Hip_y" gear="300"/>
    <motor name="R_Hip_z" joint="R_Hip_z" gear="100"/>
    <motor name="R_Knee_x" joint="R_Knee_x" gear="75"/>
    <motor name="R_Knee_y" joint="R_Knee_y" gear="100"/>
    <motor name="R_Knee_z" joint="R_Knee_z" gear="50"/>
    <motor name="R_Ankle_x" joint="R_Ankle_x" gear="75"/>
    <motor name="R_Ankle_y" joint="R_Ankle_y" gear="100"/>
    <motor name="R_Ankle_z" joint="R_Ankle_z" gear="50"/>
    <motor name="R_Toe_x" joint="R_Toe_x" gear="25"/>
    <motor name="R_Toe_y" joint="R_Toe_y" gear="25"/>
    <motor name="R_Toe_z" joint="R_Toe_z" gear="25"/>
    <motor name="Torso_x" joint="Torso_x" gear="100"/>
    <motor name="Torso_y" joint="Torso_y" gear="50"/>
    <motor name="Torso_z" joint="Torso_z" gear="100"/>
    <motor name="Spine_x" joint="Spine_x" gear="100"/>
    <motor name="Spine_y" joint="Spine_y" gear="50"/>
    <motor name="Spine_z" joint="Spine_z" gear="100"/>
    <motor name="Chest_x" joint="Chest_x" gear="25"/>
    <motor name="Chest_y" joint="Chest_y" gear="25"/>
    <motor name="Chest_z" joint="Chest_z" gear="25"/>
    <motor name="Neck_x" joint="Neck_x" gear="50"/>
    <motor name="Neck_y" joint="Neck_y" gear="50"/>
    <motor name="Neck_z" joint="Neck_z" gear="50"/>
    <motor name="Head_x" joint="Head_x" gear="50"/>
    <motor name="Head_y" joint="Head_y" gear="50"/>
    <motor name="Head_z" joint="Head_z" gear="50"/>
    <motor name="L_Thorax_x" joint="L_Thorax_x" gear="500"/>
    <motor name="L_Thorax_y" joint="L_Thorax_y" gear="500"/>
    <motor name="L_Thorax_z" joint="L_Thorax_z" gear="500"/>
    <motor name="L_Shoulder_x" joint="L_Shoulder_x" gear="500"/>
    <motor name="L_Shoulder_y" joint="L_Shoulder_y" gear="500"/>
    <motor name="L_Shoulder_z" joint="L_Shoulder_z" gear="500"/>
    <motor name="L_Elbow_x" joint="L_Elbow_x" gear="500"/>
    <motor name="L_Elbow_y" joint="L_Elbow_y" gear="500"/>
    <motor name="L_Elbow_z" joint="L_Elbow_z" gear="500"/>
    <motor name="L_Wrist_x" joint="L_Wrist_x" gear="500"/>
    <motor name="L_Wrist_y" joint="L_Wrist_y" gear="500"/>
    <motor name="L_Wrist_z" joint="L_Wrist_z" gear="500"/>
    <motor name="L_Hand_x" joint="L_Hand_x" gear="500"/>
    <motor name="L_Hand_y" joint="L_Hand_y" gear="500"/>
    <motor name="L_Hand_z" joint="L_Hand_z" gear="500"/>
    <motor name="R_Thorax_x" joint="R_Thorax_x" gear="500"/>
    <motor name="R_Thorax_y" joint="R_Thorax_y" gear="500"/>
    <motor name="R_Thorax_z" joint="R_Thorax_z" gear="500"/>
    <motor name="R_Shoulder_x" joint="R_Shoulder_x" gear="500"/>
    <motor name="R_Shoulder_y" joint="R_Shoulder_y" gear="500"/>
    <motor name="R_Shoulder_z" joint="R_Shoulder_z" gear="500"/>
    <motor name="R_Elbow_x" joint="R_Elbow_x" gear="500"/>
    <motor name="R_Elbow_y" joint="R_Elbow_y" gear="500"/>
    <motor name="R_Elbow_z" joint="R_Elbow_z" gear="500"/>
    <motor name="R_Wrist_x" joint="R_Wrist_x" gear="500"/>
    <motor name="R_Wrist_y" joint="R_Wrist_y" gear="500"/>
    <motor name="R_Wrist_z" joint="R_Wrist_z" gear="500"/>
    <motor name="R_Hand_x" joint="R_Hand_x" gear="500"/>
    <motor name="R_Hand_y" joint="R_Hand_y" gear="500"/>
    <motor name="R_Hand_z" joint="R_Hand_z" gear="500"/>

    <!-- <position joint="L_Hip_z_transl" />
    <position joint="L_Knee_z_transl" />
    <position joint="L_Ankle_z_transl" />
    <position joint="L_Toe_x_transl" />
    <position joint="R_Hip_z_transl" />
    <position joint="R_Knee_z_transl" />
    <position joint="R_Ankle_z_transl" />
    <position joint="R_Toe_x_transl" />
    <position joint="Torso_z_transl" />
    <position joint="Spine_z_transl" />
    <position joint="Chest_z_transl" />
    <position joint="Neck_z_transl" />
    <position joint="Head_z_transl" />
    <position joint="L_Thorax_y_transl" />
    <position joint="L_Shoulder_y_transl" />
    <position joint="L_Elbow_y_transl" />
    <position joint="L_Wrist_y_transl" />
    <position joint="L_Hand_y_transl" />
    <position joint="R_Thorax_y_transl" />
    <position joint="R_Shoulder_y_transl" />
    <position joint="R_Elbow_y_transl" />
    <position joint="R_Wrist_y_transl" />
    <position joint="R_Hand_y_transl" /> -->
  </actuator>
  <contact/>
  <size njmax="700" nconmax="700"/>
</mujoco>